<?xml version="1.0" encoding="UTF-8"?>
<testng-results skipped="0" failed="4" ignored="0" total="6" passed="2">
  <reporter-output>
  </reporter-output>
  <suite name="testcase_suite" duration-ms="24466" started-at="2020-06-17T07:18:27 UTC" finished-at="2020-06-17T07:18:51 UTC">
    <groups>
    </groups>
    <test name="Group1" duration-ms="9177" started-at="2020-06-17T07:18:27 UTC" finished-at="2020-06-17T07:18:36 UTC">
      <class name="POM.GoogleDemo">
        <test-method status="PASS" signature="beforeTest()[pri:0, instance:POM.GoogleDemo@1dfe2924]" name="beforeTest" is-config="true" duration-ms="4901" started-at="2020-06-17T07:18:29 UTC" finished-at="2020-06-17T07:18:34 UTC">
          <reporter-output>
          </reporter-output>
        </test-method> <!-- beforeTest -->
        <test-method status="PASS" signature="TestAssert()[pri:0, instance:POM.GoogleDemo@1dfe2924]" name="TestAssert" duration-ms="26" started-at="2020-06-17T07:18:34 UTC" finished-at="2020-06-17T07:18:34 UTC">
          <reporter-output>
          </reporter-output>
        </test-method> <!-- TestAssert -->
        <test-method status="PASS" signature="TestAssertB()[pri:0, instance:POM.GoogleDemo@1dfe2924]" name="TestAssertB" duration-ms="4" started-at="2020-06-17T07:18:34 UTC" finished-at="2020-06-17T07:18:34 UTC">
          <reporter-output>
          </reporter-output>
        </test-method> <!-- TestAssertB -->
        <test-method status="FAIL" signature="TestAssertB1()[pri:0, instance:POM.GoogleDemo@1dfe2924]" name="TestAssertB1" duration-ms="2" started-at="2020-06-17T07:18:34 UTC" finished-at="2020-06-17T07:18:34 UTC">
          <exception class="java.lang.AssertionError">
            <message>
              <![CDATA[expected [some wrong Titile] but found [Google]]]>
            </message>
            <full-stacktrace>
              <![CDATA[java.lang.AssertionError: expected [some wrong Titile] but found [Google]
at org.testng.Assert.fail(Assert.java:97)
at org.testng.Assert.assertEqualsImpl(Assert.java:136)
at org.testng.Assert.assertEquals(Assert.java:118)
at org.testng.Assert.assertEquals(Assert.java:575)
at org.testng.Assert.assertEquals(Assert.java:585)
at POM.GoogleDemo.TestAssertB1(GoogleDemo.java:40)
at sun.reflect.NativeMethodAccessorImpl.invoke0(Native Method)
at sun.reflect.NativeMethodAccessorImpl.invoke(Unknown Source)
at sun.reflect.DelegatingMethodAccessorImpl.invoke(Unknown Source)
at java.lang.reflect.Method.invoke(Unknown Source)
at org.testng.internal.MethodInvocationHelper.invokeMethod(MethodInvocationHelper.java:133)
at org.testng.internal.TestInvoker.invokeMethod(TestInvoker.java:584)
at org.testng.internal.TestInvoker.invokeTestMethod(TestInvoker.java:172)
at org.testng.internal.MethodRunner.runInSequence(MethodRunner.java:46)
at org.testng.internal.TestInvoker$MethodInvocationAgent.invoke(TestInvoker.java:804)
at org.testng.internal.TestInvoker.invokeTestMethods(TestInvoker.java:145)
at org.testng.internal.TestMethodWorker.invokeTestMethods(TestMethodWorker.java:146)
at org.testng.internal.TestMethodWorker.run(TestMethodWorker.java:128)
at java.util.ArrayList.forEach(Unknown Source)
at org.testng.TestRunner.privateRun(TestRunner.java:770)
at org.testng.TestRunner.run(TestRunner.java:591)
at org.testng.SuiteRunner.runTest(SuiteRunner.java:402)
at org.testng.SuiteRunner.runSequentially(SuiteRunner.java:396)
at org.testng.SuiteRunner.privateRun(SuiteRunner.java:355)
at org.testng.SuiteRunner.run(SuiteRunner.java:304)
at org.testng.SuiteRunnerWorker.runSuite(SuiteRunnerWorker.java:53)
at org.testng.SuiteRunnerWorker.run(SuiteRunnerWorker.java:96)
at org.testng.TestNG.runSuitesSequentially(TestNG.java:1180)
at org.testng.TestNG.runSuitesLocally(TestNG.java:1102)
at org.testng.TestNG.runSuites(TestNG.java:1032)
at org.testng.TestNG.run(TestNG.java:1000)
at org.testng.remote.AbstractRemoteTestNG.run(AbstractRemoteTestNG.java:115)
at org.testng.remote.RemoteTestNG.initAndRun(RemoteTestNG.java:251)
at org.testng.remote.RemoteTestNG.main(RemoteTestNG.java:77)
]]>
            </full-stacktrace>
          </exception> <!-- java.lang.AssertionError -->
          <reporter-output>
          </reporter-output>
        </test-method> <!-- TestAssertB1 -->
        <test-method status="PASS" signature="afterTest()[pri:0, instance:POM.GoogleDemo@1dfe2924]" name="afterTest" is-config="true" duration-ms="1" started-at="2020-06-17T07:18:36 UTC" finished-at="2020-06-17T07:18:36 UTC">
          <reporter-output>
          </reporter-output>
        </test-method> <!-- afterTest -->
      </class> <!-- POM.GoogleDemo -->
      <class name="POM.VerifyLogin_PgFactory">
        <test-method status="FAIL" signature="ValidLogin__fact()[pri:0, instance:POM.VerifyLogin_PgFactory@6ebc05a6]" name="ValidLogin__fact" duration-ms="1344" started-at="2020-06-17T07:18:34 UTC" finished-at="2020-06-17T07:18:36 UTC">
          <exception class="java.lang.NullPointerException">
            <full-stacktrace>
              <![CDATA[java.lang.NullPointerException
at POM.VerifyLogin_PgFactory.ValidLogin__fact(VerifyLogin_PgFactory.java:43)
at sun.reflect.NativeMethodAccessorImpl.invoke0(Native Method)
at sun.reflect.NativeMethodAccessorImpl.invoke(Unknown Source)
at sun.reflect.DelegatingMethodAccessorImpl.invoke(Unknown Source)
at java.lang.reflect.Method.invoke(Unknown Source)
at org.testng.internal.MethodInvocationHelper.invokeMethod(MethodInvocationHelper.java:133)
at org.testng.internal.TestInvoker.invokeMethod(TestInvoker.java:584)
at org.testng.internal.TestInvoker.invokeTestMethod(TestInvoker.java:172)
at org.testng.internal.MethodRunner.runInSequence(MethodRunner.java:46)
at org.testng.internal.TestInvoker$MethodInvocationAgent.invoke(TestInvoker.java:804)
at org.testng.internal.TestInvoker.invokeTestMethods(TestInvoker.java:145)
at org.testng.internal.TestMethodWorker.invokeTestMethods(TestMethodWorker.java:146)
at org.testng.internal.TestMethodWorker.run(TestMethodWorker.java:128)
at java.util.ArrayList.forEach(Unknown Source)
at org.testng.TestRunner.privateRun(TestRunner.java:770)
at org.testng.TestRunner.run(TestRunner.java:591)
at org.testng.SuiteRunner.runTest(SuiteRunner.java:402)
at org.testng.SuiteRunner.runSequentially(SuiteRunner.java:396)
at org.testng.SuiteRunner.privateRun(SuiteRunner.java:355)
at org.testng.SuiteRunner.run(SuiteRunner.java:304)
at org.testng.SuiteRunnerWorker.runSuite(SuiteRunnerWorker.java:53)
at org.testng.SuiteRunnerWorker.run(SuiteRunnerWorker.java:96)
at org.testng.TestNG.runSuitesSequentially(TestNG.java:1180)
at org.testng.TestNG.runSuitesLocally(TestNG.java:1102)
at org.testng.TestNG.runSuites(TestNG.java:1032)
at org.testng.TestNG.run(TestNG.java:1000)
at org.testng.remote.AbstractRemoteTestNG.run(AbstractRemoteTestNG.java:115)
at org.testng.remote.RemoteTestNG.initAndRun(RemoteTestNG.java:251)
at org.testng.remote.RemoteTestNG.main(RemoteTestNG.java:77)
]]>
            </full-stacktrace>
          </exception> <!-- java.lang.NullPointerException -->
          <reporter-output>
          </reporter-output>
        </test-method> <!-- ValidLogin__fact -->
      </class> <!-- POM.VerifyLogin_PgFactory -->
    </test> <!-- Group1 -->
    <test name="Group2" duration-ms="14800" started-at="2020-06-17T07:18:37 UTC" finished-at="2020-06-17T07:18:51 UTC">
      <class name="POM.VerifyLogin_PgFactory">
        <test-method status="FAIL" signature="ValidLogin__fact()[pri:0, instance:POM.VerifyLogin_PgFactory@711f39f9]" name="ValidLogin__fact" duration-ms="1443" started-at="2020-06-17T07:18:50 UTC" finished-at="2020-06-17T07:18:51 UTC">
          <exception class="java.lang.NullPointerException">
            <full-stacktrace>
              <![CDATA[java.lang.NullPointerException
at POM.VerifyLogin_PgFactory.ValidLogin__fact(VerifyLogin_PgFactory.java:43)
at sun.reflect.NativeMethodAccessorImpl.invoke0(Native Method)
at sun.reflect.NativeMethodAccessorImpl.invoke(Unknown Source)
at sun.reflect.DelegatingMethodAccessorImpl.invoke(Unknown Source)
at java.lang.reflect.Method.invoke(Unknown Source)
at org.testng.internal.MethodInvocationHelper.invokeMethod(MethodInvocationHelper.java:133)
at org.testng.internal.TestInvoker.invokeMethod(TestInvoker.java:584)
at org.testng.internal.TestInvoker.invokeTestMethod(TestInvoker.java:172)
at org.testng.internal.MethodRunner.runInSequence(MethodRunner.java:46)
at org.testng.internal.TestInvoker$MethodInvocationAgent.invoke(TestInvoker.java:804)
at org.testng.internal.TestInvoker.invokeTestMethods(TestInvoker.java:145)
at org.testng.internal.TestMethodWorker.invokeTestMethods(TestMethodWorker.java:146)
at org.testng.internal.TestMethodWorker.run(TestMethodWorker.java:128)
at java.util.ArrayList.forEach(Unknown Source)
at org.testng.TestRunner.privateRun(TestRunner.java:770)
at org.testng.TestRunner.run(TestRunner.java:591)
at org.testng.SuiteRunner.runTest(SuiteRunner.java:402)
at org.testng.SuiteRunner.runSequentially(SuiteRunner.java:396)
at org.testng.SuiteRunner.privateRun(SuiteRunner.java:355)
at org.testng.SuiteRunner.run(SuiteRunner.java:304)
at org.testng.SuiteRunnerWorker.runSuite(SuiteRunnerWorker.java:53)
at org.testng.SuiteRunnerWorker.run(SuiteRunnerWorker.java:96)
at org.testng.TestNG.runSuitesSequentially(TestNG.java:1180)
at org.testng.TestNG.runSuitesLocally(TestNG.java:1102)
at org.testng.TestNG.runSuites(TestNG.java:1032)
at org.testng.TestNG.run(TestNG.java:1000)
at org.testng.remote.AbstractRemoteTestNG.run(AbstractRemoteTestNG.java:115)
at org.testng.remote.RemoteTestNG.initAndRun(RemoteTestNG.java:251)
at org.testng.remote.RemoteTestNG.main(RemoteTestNG.java:77)
]]>
            </full-stacktrace>
          </exception> <!-- java.lang.NullPointerException -->
          <reporter-output>
          </reporter-output>
        </test-method> <!-- ValidLogin__fact -->
      </class> <!-- POM.VerifyLogin_PgFactory -->
      <class name="POM.excelloop">
        <test-method status="PASS" signature="beforeTest()[pri:0, instance:POM.excelloop@3fd7a715]" name="beforeTest" is-config="true" duration-ms="2043" started-at="2020-06-17T07:18:38 UTC" finished-at="2020-06-17T07:18:40 UTC">
          <reporter-output>
          </reporter-output>
        </test-method> <!-- beforeTest -->
        <test-method status="FAIL" signature="ReadWrite()[pri:0, instance:POM.excelloop@3fd7a715]" name="ReadWrite" duration-ms="9403" started-at="2020-06-17T07:18:40 UTC" finished-at="2020-06-17T07:18:49 UTC">
          <exception class="java.io.FileNotFoundException">
            <message>
              <![CDATA[C:\Bhavya\ddt_demo.xlsx (The process cannot access the file because it is being used by another process)]]>
            </message>
            <full-stacktrace>
              <![CDATA[java.io.FileNotFoundException: C:\Bhavya\ddt_demo.xlsx (The process cannot access the file because it is being used by another process)
at java.io.FileOutputStream.open0(Native Method)
at java.io.FileOutputStream.open(Unknown Source)
at java.io.FileOutputStream.<init>(Unknown Source)
at java.io.FileOutputStream.<init>(Unknown Source)
at POM.excelloop.ReadWrite(excelloop.java:91)
at sun.reflect.NativeMethodAccessorImpl.invoke0(Native Method)
at sun.reflect.NativeMethodAccessorImpl.invoke(Unknown Source)
at sun.reflect.DelegatingMethodAccessorImpl.invoke(Unknown Source)
at java.lang.reflect.Method.invoke(Unknown Source)
at org.testng.internal.MethodInvocationHelper.invokeMethod(MethodInvocationHelper.java:133)
at org.testng.internal.TestInvoker.invokeMethod(TestInvoker.java:584)
at org.testng.internal.TestInvoker.invokeTestMethod(TestInvoker.java:172)
at org.testng.internal.MethodRunner.runInSequence(MethodRunner.java:46)
at org.testng.internal.TestInvoker$MethodInvocationAgent.invoke(TestInvoker.java:804)
at org.testng.internal.TestInvoker.invokeTestMethods(TestInvoker.java:145)
at org.testng.internal.TestMethodWorker.invokeTestMethods(TestMethodWorker.java:146)
at org.testng.internal.TestMethodWorker.run(TestMethodWorker.java:128)
at java.util.ArrayList.forEach(Unknown Source)
at org.testng.TestRunner.privateRun(TestRunner.java:770)
at org.testng.TestRunner.run(TestRunner.java:591)
at org.testng.SuiteRunner.runTest(SuiteRunner.java:402)
at org.testng.SuiteRunner.runSequentially(SuiteRunner.java:396)
at org.testng.SuiteRunner.privateRun(SuiteRunner.java:355)
at org.testng.SuiteRunner.run(SuiteRunner.java:304)
at org.testng.SuiteRunnerWorker.runSuite(SuiteRunnerWorker.java:53)
at org.testng.SuiteRunnerWorker.run(SuiteRunnerWorker.java:96)
at org.testng.TestNG.runSuitesSequentially(TestNG.java:1180)
at org.testng.TestNG.runSuitesLocally(TestNG.java:1102)
at org.testng.TestNG.runSuites(TestNG.java:1032)
at org.testng.TestNG.run(TestNG.java:1000)
at org.testng.remote.AbstractRemoteTestNG.run(AbstractRemoteTestNG.java:115)
at org.testng.remote.RemoteTestNG.initAndRun(RemoteTestNG.java:251)
at org.testng.remote.RemoteTestNG.main(RemoteTestNG.java:77)
]]>
            </full-stacktrace>
          </exception> <!-- java.io.FileNotFoundException -->
          <reporter-output>
          </reporter-output>
        </test-method> <!-- ReadWrite -->
      </class> <!-- POM.excelloop -->
    </test> <!-- Group2 -->
  </suite> <!-- testcase_suite -->
</testng-results>
